------------------------
2022-09-25 13:29:15,988 
------------------------
 ExtractDataServiceProvider.py:  
             
 [Errno 2] No such file or directory: '../Data2bot-Assessment/data/raw/orders.csv.73cae9aC' 
  @ execute_service: /Users/cosmoremit/Documents/AcNice/data2bot/scripts/Providers/ExtractDataServiceProvider.py
------------------------
2022-09-25 13:29:17,257 
------------------------
 ExtractDataServiceProvider.py:  
             
 [Errno 2] No such file or directory: '../Data2bot-Assessment/data/raw/reviews.csv.fac2C97E' 
  @ execute_service: /Users/cosmoremit/Documents/AcNice/data2bot/scripts/Providers/ExtractDataServiceProvider.py
------------------------
2022-09-25 13:29:32,794 
------------------------
 ExtractDataServiceProvider.py:  
             
 [Errno 2] No such file or directory: '../Data2bot-Assessment/data/raw/shipment_deliveries.csv.EBAdc93E' 
  @ execute_service: /Users/cosmoremit/Documents/AcNice/data2bot/scripts/Providers/ExtractDataServiceProvider.py
------------------------
2022-09-25 13:29:32,824 
------------------------
 DataLoadServiceProvider.py:  
             
 [Errno 2] No such file or directory: '../Data2bot-Assessment/data/raw/orders.csv' 
  @ execute_service: /Users/cosmoremit/Documents/AcNice/data2bot/scripts/Providers/DataLoadServiceProvider.py
------------------------
2022-09-25 19:24:23,700 
------------------------
 ExtractDataServiceProvider.py:  
             
 Could not connect to the endpoint URL: "https://d2b-internal-assessment-bucket.s3.amazonaws.com/orders_data/orders.csv" 
  @ execute_service: /Users/cosmoremit/Documents/AcNice/data2bot/scripts/Providers/ExtractDataServiceProvider.py
------------------------
2022-09-25 19:24:29,616 
------------------------
 ExtractDataServiceProvider.py:  
             
 Could not connect to the endpoint URL: "https://d2b-internal-assessment-bucket.s3.amazonaws.com/orders_data/reviews.csv" 
  @ execute_service: /Users/cosmoremit/Documents/AcNice/data2bot/scripts/Providers/ExtractDataServiceProvider.py
------------------------
2022-09-25 19:24:35,807 
------------------------
 ExtractDataServiceProvider.py:  
             
 Could not connect to the endpoint URL: "https://d2b-internal-assessment-bucket.s3.amazonaws.com/orders_data/shipment_deliveries.csv" 
  @ execute_service: /Users/cosmoremit/Documents/AcNice/data2bot/scripts/Providers/ExtractDataServiceProvider.py
------------------------
2022-09-25 19:24:35,864 
------------------------
 DataLoadServiceProvider.py:  
             
 (psycopg2.OperationalError) could not translate host name "d2b-internal-assessment-dwh.cxeuj0ektqdz.eu-central-1.rds.amazonaws.com" to address: nodename nor servname provided, or not known

(Background on this error at: https://sqlalche.me/e/14/e3q8) 
  @ execute_service: /Users/cosmoremit/Documents/AcNice/data2bot/scripts/Providers/DataLoadServiceProvider.py
------------------------
2022-09-25 19:24:35,866 
------------------------
 db_connect_handler.py:  
             
 could not translate host name "d2b-internal-assessment-dwh.cxeuj0ektqdz.eu-central-1.rds.amazonaws.com" to address: nodename nor servname provided, or not known
 
  @ connect: /Users/cosmoremit/Documents/AcNice/data2bot/scripts/Handlers/db_connect_handler.py
